<mujoco model="Skydio X2 scene">
  <include file="x2.xml" />

  <statistic center="0 0 0.1" extent="0.6" meansize=".05"/>

  <visual>
    <headlight diffuse="0.6 0.6 0.6" ambient="0.3 0.3 0.3" specular="0 0 0"/>
    <rgba haze="0.15 0.25 0.35 1"/>
    <global azimuth="-20" elevation="-20" ellipsoidinertia="true"/>
  </visual>

  <asset>
    <texture type="skybox" builtin="gradient" rgb1="0.3 0.5 0.7" rgb2="0 0 0" width="512" height="3072"/>
    <texture type="2d" name="groundplane" builtin="checker" mark="edge" rgb1="0.2 0.3 0.4" rgb2="0.1 0.2 0.3"
      markrgb="0.8 0.8 0.8" width="300" height="300"/>
    <material name="groundplane" texture="groundplane" texuniform="true" texrepeat="5 5" reflectance="0.2"/>
    <texture name="donut_tex" type="2d" file="donut_texture.png"/>
    <material name="donut_material" texture="donut_tex" texrepeat="1 1" texuniform="true"/>
  </asset>

  <worldbody>
    <light pos="0 0 1.5" dir="0 0 -1" directional="true"/>
    <geom name="floor" size="0 0 0.05" type="plane" material="groundplane"/>
    <body name="platform" pos="0 0 0.1">
      <joint name="platform_x" type="slide" axis="1 0 0" damping="5"/>
      <joint name="platform_y" type="slide" axis="0 1 0" damping="5"/>
      <geom name="donut_platform" type="cylinder" size="1.0 0.005" material="donut_material" rgba="1 1 1 1"
        condim="4" friction="1.5 1.5 0.001" solref="0.001 0.2" solimp="0.6 0.95 0.001"/>
    </body>
  </worldbody>
  
</mujoco>
